<?xml version="1.0" encoding="utf-8"?>
<robot name="rectbot">

  <link name="base_footprint"/>

  <joint name="base_joint" type="fixed">
    <parent link="base_footprint"/>
    <child link="base_link"/>
    <origin xyz="0 0 0.055" rpy="0 0 0"/>
  </joint>

  <link name="base_link">
    <inertial>
      <origin xyz="-0.0090897 -0.00057293 0.056052" rpy="0 0 0" />
      <mass value="1.3" />
      <inertia ixx="0.002002649" ixy="0" ixz="0"
               iyy="0.002237316" iyz="0"
               izz="0.004187977" />
    </inertial>
    <visual>
      <origin xyz="0 0 0" rpy="0 0 0" />
      <geometry>
        <mesh filename="package://rectbot_description/meshes/base_link.STL" />
      </geometry>
      <material name="white">
        <color rgba="1 1 1 1" />
      </material>
    </visual>
    <collision>
      <origin xyz="-0.005 0 0.0775" rpy="0 0 0" />
      <geometry>
        <box size="0.18 0.18 0.155"/>
      </geometry>
    </collision>
  </link>

  <link name="left_wheel_link">
    <inertial>
      <origin xyz="0 0 0" rpy="0 0 0" />
      <mass value="0.05" />
      <inertia ixx="2.19136097E-05" ixy="0" ixz="0"
               iyy="3.68739994E-05" iyz="0"
               izz="2.19509956E-05" />
    </inertial>
    <visual>
      <origin xyz="0 0 0" rpy="0 0 0" />
      <geometry>
        <mesh filename="package://rectbot_description/meshes/left_wheel_link.STL" />
      </geometry>
      <material name="black">
        <color rgba="0 0 0 1" />
      </material>
    </visual>
    <collision>
      <origin xyz="0 0.0125 0" rpy="-1.57 0 0" />
      <geometry>
        <cylinder length="0.025" radius="0.0325"/>
      </geometry>3.9044
    </collision>
  </link>

  <joint name="left_wheel_joint" type="continuous">
    <origin xyz="-0.038393 0.055 -0.0225" rpy="0 0 0" />
    <parent link="base_link" />
    <child link="left_wheel_link" />
    <axis xyz="0 1 0" />
  </joint>

  <transmission name="left_wheel_trans">
    <type>transmission_interface/SimpleTransmission</type>
    <joint name="left_wheel_joint">
      <hardwareInterface>hardware_interface/VelocityJointInterface</hardwareInterface>
    </joint>
    <actuator name="left_wheel_motor">
      <hardwareInterface>hardware_interface/VelocityJointInterface</hardwareInterface>
      <mechanicalReduction>1</mechanicalReduction>
    </actuator>
  </transmission>

  <link name="right_wheel_link">
    <inertial>
      <origin xyz="0 0 0" rpy="0 0 0" />
      <mass value="0.05" />
      <inertia ixx="2.19136097E-05" ixy="0" ixz="0"
               iyy="3.68739994E-05" iyz="0"
               izz="2.19509956E-05" />
    </inertial>
    <visual>
      <origin xyz="0 0 0" rpy="0 0 0" />
      <geometry>
        <mesh filename="package://rectbot_description/meshes/right_wheel_link.STL" />
      </geometry>
      <material name="black">
        <color rgba="0 0 0 1" />
      </material>
    </visual>
    <collision>
      <origin xyz="0 -0.0125 0" rpy="-1.57 0 0" />
      <geometry>
        <cylinder length="0.025" radius="0.0325"/>
      </geometry>
    </collision>
  </link>

  <joint name="right_wheel_joint" type="continuous">
    <origin xyz="-0.038393 -0.055 -0.0225" rpy="0 0 0" />
    <parent link="base_link" />
    <child link="right_wheel_link" />
    <axis xyz="0 1 0" />
  </joint>

  <transmission name="right_wheel_trans">
    <type>transmission_interface/SimpleTransmission</type>
    <joint name="right_wheel_joint">
      <hardwareInterface>hardware_interface/VelocityJointInterface</hardwareInterface>
    </joint>
    <actuator name="right_wheel_motor">
      <hardwareInterface>hardware_interface/VelocityJointInterface</hardwareInterface>
      <mechanicalReduction>1</mechanicalReduction>
    </actuator>
  </transmission>

  <link name="left_wing_link">
    <inertial> 
      <origin xyz="0.083733 0.023264 0.002" rpy="0 0 0" />
      <mass value="0.02" />
      <inertia ixx="6.983090931E-06" ixy="-5.077687122E-06" ixz="0"
               iyy="2.384927673E-05" iyz="0"
               izz="3.077844783E-05" />
    </inertial>
    <visual>
      <origin xyz="0 0 0" rpy="0 0 0" />
      <geometry>
        <mesh filename="package://rectbot_description/meshes/left_wing_link.STL" />
      </geometry>
      <material name="green">
        <color rgba="0 1 0 1" />
      </material>
    </visual>
    <collision>
      <origin xyz="0 0 0" rpy="0 0 0" />
      <geometry>
        <mesh filename="package://rectbot_description/meshes/left_wing_link.STL" />
      </geometry>
    </collision>
  </link>

  <joint name="left_wing_joint" type="revolute">
    <origin xyz="-0.069779 0.079 0.0995" rpy="0 0 0" />
    <parent link="base_link" />
    <child link="left_wing_link" />
    <axis xyz="0 0 -1" />
    <limit lower="0" upper="0.6" effort="1" velocity="1" />
  </joint>

  <transmission name="left_wing_trans">
    <type>transmission_interface/SimpleTransmission</type>
    <joint name="left_wing_joint">
      <hardwareInterface>hardware_interface/PositionJointInterface</hardwareInterface>
    </joint>
    <actuator name="left_wing_motor">
      <hardwareInterface>hardware_interface/PositionJointInterface</hardwareInterface>
      <mechanicalReduction>1</mechanicalReduction>
    </actuator>
  </transmission>

  <link name="right_wing_link">
    <inertial>
      <origin xyz="0.083894 -0.022676 0.002" rpy="0 0 0" />
      <mass value="0.02" />
      <inertia ixx="6.912932088E-06" ixy="4.959284221E-06" ixz="0"
               iyy="2.391943557E-05" iyz="0"
               izz="3.077844783E-05" />
    </inertial>
    <visual>
      <origin xyz="0 0 0" rpy="0 0 0" />
      <geometry>
        <mesh filename="package://rectbot_description/meshes/right_wing_link.STL" />
      </geometry>
      <material name="green">
        <color rgba="0 1 0 1" />
      </material>
    </visual>
    <collision>
      <origin xyz="0 0 0" rpy="0 0 0" />
      <geometry>
        <mesh filename="package://rectbot_description/meshes/right_wing_link.STL" />
      </geometry>
    </collision>
  </link>

  <joint name="right_wing_joint" type="revolute">
    <origin xyz="-0.068377 -0.0788 0.0995" rpy="0 0 0" />
    <parent link="base_link" />
    <child link="right_wing_link" />
    <axis xyz="0 0 1" />
    <limit lower="0" upper="0.6" effort="1" velocity="1" />
  </joint>

  <transmission name="right_wing_trans">
    <type>transmission_interface/SimpleTransmission</type>
    <joint name="right_wing_joint">
      <hardwareInterface>hardware_interface/PositionJointInterface</hardwareInterface>
    </joint>
    <actuator name="right_wing_motor">
      <hardwareInterface>hardware_interface/PositionJointInterface</hardwareInterface>
      <mechanicalReduction>1</mechanicalReduction>
    </actuator>
  </transmission>

  <link name="caster_link">
    <inertial>
      <origin xyz="2.7756E-17 4.1633E-17 -0.045233" rpy="0 0 0" />
      <mass value="0.04" />
      <inertia ixx="29.119577105E-07" ixy="0" ixz="0"
               iyy="24.748450602E-07" iyz="0"
               izz="33.014339532E-07" />
    </inertial>
    <visual>
      <origin xyz="0 0 0" rpy="0 0 0" />
      <geometry>
        <mesh filename="package://rectbot_description/meshes/caster_link.STL" />
      </geometry>
      <material name="gray">
        <color rgba="0.79216 0.81961 0.93333 1" />
      </material>
    </visual>
    <collision>
      <origin xyz="0 0 -0.0275" rpy="0 0 0" />
      <geometry>
        <cylinder length="0.055" radius="0.015"/>
      </geometry>
    </collision>
  </link>

  <joint name="caster_joint" type="fixed">
    <origin xyz="0.065438 0 0" rpy="0 0 0" />
    <parent link="base_link" />
    <child link="caster_link" />
    <axis xyz="0 0 0" />
  </joint>

  <link name="imu_link"/>

  <joint name="imu_joint" type="fixed">
    <parent link="base_link"/>
    <child link="imu_link"/>
    <origin xyz="-0.08 0.0 0.09" rpy="0 0 0"/>
  </joint>

  <link name="camera_link">
    <inertial>
      <!-- <origin xyz="-0.013049 0.00024621 0.0099394" rpy="0 0 0" /> -->
      <origin xyz="0.0 -0.025 0.0" rpy="0 0 0" />
      <!-- <origin xyz="0.0 0.0 0.0" rpy="0.0 0.0 0.0"/> -->
      
      <mass value="0.26" />
      <inertia ixx="15.84796210E-05" ixy="0" ixz="0"
               iyy="22.91790311E-06" iyz="0"
               izz="15.89676439E-05" />
    </inertial>
    <visual>
      <!-- <origin xyz="0 0 0" rpy="0 0 0" /> -->
      <origin xyz="-0.01 -0.0175 0.0" rpy="0 0 0" />
      <geometry>
        <mesh filename="package://rectbot_description/meshes/camera_link.STL" />
      </geometry>
      <material name="gray">
        <color rgba="0.79216 0.81961 0.93333 1" />
      </material>
    </visual>
    <collision>
      <origin xyz="0 0 0" rpy="0 0 0" />
      <geometry>
        <mesh filename="package://rectbot_description/meshes/camera_link.STL" />
      </geometry>
    </collision>
  </link>

  <joint name="camera_joint" type="fixed">
    <!-- <origin xyz="0.082529 -0.0026396 0.1145" rpy="0 0 0" /> -->
    <origin xyz="0.12085 0.0175 0.09" rpy="0.0 0.0 0.0"/>
    
    <parent link="base_link" />
    <child link="camera_link" />
    <axis xyz="0 0 0" />
  </joint>

  <link name="lidar_link">
    <inertial>
      <origin xyz="-0.00036629 -7.172E-06 0.019067" rpy="0 0 0" />
      <mass value="0.43" />
      <inertia ixx="20.258581731E-05" ixy="0" ixz="0"
               iyy="19.877938699E-05" iyz="0"
               izz="0.000290405" />
    </inertial>
    <visual>
      <origin xyz="0 0 0" rpy="0 0 0" />
      <geometry>
        <mesh filename="package://rectbot_description/meshes/lidar_link.STL" />
      </geometry>
      <material name="black">
        <color rgba="0 0 0 1" />
      </material>
    </visual>
    <collision>
      <origin xyz="0 0 0" rpy="0 0 0" />
      <geometry>
        <mesh filename="package://rectbot_description/meshes/lidar_link.STL" />
      </geometry>
    </collision>
  </link>

  <joint name="lidar_joint" type="fixed">
    <origin xyz="-0.0068617 0 0.103" rpy="0 0 3.14" />
    <parent link="base_link" />
    <child link="lidar_link" />
    <axis xyz="0 0 0" />
  </joint>
</robot>
